Workbook
Name LIV_Code: 'Livres'!$E$7:$E$306
Name LIV_Titre: 'Livres'!$G$7:$G$306
Name LIV_Auteur: 'Livres'!$H$7:$H$306
Name LIV_Cat: 'Livres'!$I$7:$I$306
Name LIV_Ex: 'Livres'!$L$7:$L$306
Name LIV_Emp: 'Livres'!$N$7:$N$306
Name LIV_Dispo: 'Livres'!$O$7:$O$306
Name LIV_Total: 'Livres'!$P$7:$P$306
Name LIV_Statut: 'Livres'!$Q$7:$Q$306
Name LIV_Score: 'Livres'!$S$7:$S$306
Name LIV_Rech: 'Livres'!$T$7:$T$306
Name LIV_ScoreMois: 'Livres'!$U$7:$U$306
Name EMP_Cat: 'Emprunts'!$T$7:$T$1006
Name MEM_ID: 'Membres'!$E$7:$E$306
Name MEM_Nom: 'Membres'!$F$7:$F$306
Name MEM_Type: 'Membres'!$G$7:$G$306
Name MEM_Classe: 'Membres'!$H$7:$H$306
Name MEM_Insc: 'Membres'!$J$7:$J$306
Name MEM_Cours: 'Membres'!$K$7:$K$306
Name MEM_Statut: 'Membres'!$N$7:$N$306
Name MEM_Rech: 'Membres'!$P$7:$P$306
Name EMP_Date: 'Emprunts'!$F$7:$F$1006
Name EMP_Membre: 'Emprunts'!$G$7:$G$1006
Name EMP_Nom: 'Emprunts'!$H$7:$H$1006
Name EMP_Livre: 'Emprunts'!$I$7:$I$1006
Name EMP_Titre: 'Emprunts'!$J$7:$J$1006
Name EMP_Prevu: 'Emprunts'!$K$7:$K$1006
Name EMP_Retour: 'Emprunts'!$L$7:$L$1006
Name EMP_Statut: 'Emprunts'!$M$7:$M$1006
Name EMP_Jours: 'Emprunts'!$N$7:$N$1006
Name EMP_Amende: 'Emprunts'!$O$7:$O$1006
Name EMP_Paye: 'Emprunts'!$P$7:$P$1006
Name EMP_ScoreRetard: 'Emprunts'!$R$7:$R$1006
Name EMP_ScoreRecent: 'Emprunts'!$S$7:$S$1006
Name FOU_Code: 'Fournitures'!$E$7:$E$206
Name FOU_Article: 'Fournitures'!$F$7:$F$206
Name FOU_Unite: 'Fournitures'!$H$7:$H$206
Name FOU_Seuil: 'Fournitures'!$J$7:$J$206
Name FOU_Stock: 'Fournitures'!$O$7:$O$206
Name FOU_Valeur: 'Fournitures'!$P$7:$P$206
Name FOU_Statut: 'Fournitures'!$Q$7:$Q$206
Name FOU_Score: 'Fournitures'!$S$7:$S$206
Name MOV_Date: 'Mouvements'!$F$7:$F$1006
Name MOV_Code: 'Mouvements'!$G$7:$G$1006
Name MOV_Type: 'Mouvements'!$I$7:$I$1006
Name MOV_Qte: 'Mouvements'!$J$7:$J$1006
Name P_Ecole: 'Paramètres'!$F$7
Name P_Annee: 'Paramètres'!$F$8
Name P_Duree: 'Paramètres'!$F$9
Name P_Amende: 'Paramètres'!$F$10
Name P_Max: 'Paramètres'!$F$11
Name L_CatLivres: 'Paramètres'!$I$7:$I$26
Name L_Classes: 'Paramètres'!$J$7:$J$26
Name L_TypesMembre: 'Paramètres'!$K$7:$K$9
Name L_CatFourn: 'Paramètres'!$L$7:$L$26
Name L_Unites: 'Paramètres'!$M$7:$M$26
Name L_TypesMvt: 'Paramètres'!$N$7:$N$8
Name L_OuiNon: 'Paramètres'!$O$7:$O$8
Name L_Mois: 'Calculs'!$S$2:$S$25
Name Q_Rech: TRIM('Recherche'!$F$5)

Sheet Tableau de bord
E2: Tableau de bord | O2: =HYPERLINK("#'Recherche'!F5","🔍 Rechercher un livre, un membre…") | Y2: =TODAY()
E3: ="Bonjour 👋 Bienvenue à la bibliothèque de la "&P_Ecole&" · Année scolaire "&P_Annee
E7: =HYPERLINK("#'Livres'!E6","📚 Total des livres") | J7: =HYPERLINK("#'Membres'!E6","👥 Membres") | O7: =HYPERLINK("#'Emprunts'!E6","🔄 Emprunts en cours") | T7: =HYPERLINK("#'Emprunts'!E6","📈 Emprunts ce mois") | Y7: =HYPERLINK("#'Emprunts'!E6","⏰ Livres en retard") | AD7: =HYPERLINK("#'Fournitures'!E6","📦 Alertes de stock")
E8: =SUM(LIV_Ex) | J8: =COUNTIF(MEM_ID,"?*") | O8: =COUNTIFS(EMP_Livre,"?*",EMP_Retour,"") | T8: =Calculs!K2 | Y8: =COUNTIF(EMP_Statut,"En retard") | AD8: =COUNTIF(FOU_Statut,"Stock faible")+COUNTIF(FOU_Statut,"Rupture")
E9: =COUNTIF(LIV_Code,"?*")&" titres au catalogue" | J9: =COUNTIF(MEM_Type,"Élève")&" élèves · "&COUNTIF(MEM_Type,"Enseignant")&" enseignants" | O9: =TEXT(IF(SUM(LIV_Ex)=0,0,SUM(LIV_Emp)/SUM(LIV_Ex)),"0%")&" du fonds en circulation" | T9: =IF(Calculs!M2>=0,"▲ ","▼ ")&TEXT(ABS(Calculs!M2),"0%")&" vs mois dernier" | Y9: =FIXED(SUMIFS(EMP_Amende,EMP_Paye,"<>Oui"),0)&" FC d'amendes dues" | AD9: =COUNTIF(FOU_Statut,"Rupture")&" en rupture · "&COUNTIF(FOU_Statut,"Stock faible")&" stock faible"
B12: MENU | E12: Évolution des emprunts — 30 derniers jours | P12: =HYPERLINK("#'Emprunts'!E6","Voir tout →") | T12: ="Livres par catégorie · "&FIXED(SUM(LIV_Ex),0)&" exemplaires" | AD12: 🏆 Top 5 des livres
B14: =HYPERLINK("#'Tableau de bord'!A1","▦ Tableau de bord") | X14: ● | Y14: =Calculs!E2 | AB14: =Calculs!F2 | AD14: =IFERROR("1. "&INDEX(LIV_Titre,MATCH(LARGE(LIV_Score,1),LIV_Score,0)),"") | AG14: =IFERROR(INDEX(LIV_Total,MATCH(LARGE(LIV_Score,1),LIV_Score,0)),"")
B15: =HYPERLINK("#'Livres'!A1","📚 Livres") | X15: ● | Y15: =Calculs!E3 | AB15: =Calculs!F3 | AD15: =IFERROR(" "&INDEX(LIV_Auteur,MATCH(LARGE(LIV_Score,1),LIV_Score,0)),"")
B16: =HYPERLINK("#'Membres'!A1","👥 Membres") | X16: ● | Y16: =Calculs!E4 | AB16: =Calculs!F4 | AD16: =IFERROR("2. "&INDEX(LIV_Titre,MATCH(LARGE(LIV_Score,2),LIV_Score,0)),"") | AG16: =IFERROR(INDEX(LIV_Total,MATCH(LARGE(LIV_Score,2),LIV_Score,0)),"")
B17: =HYPERLINK("#'Emprunts'!A1","🔄 Emprunts") | X17: ● | Y17: =Calculs!E5 | AB17: =Calculs!F5 | AD17: =IFERROR(" "&INDEX(LIV_Auteur,MATCH(LARGE(LIV_Score,2),LIV_Score,0)),"")
B18: =HYPERLINK("#'Fournitures'!A1","📦 Fournitures") | X18: ● | Y18: =Calculs!E6 | AB18: =Calculs!F6 | AD18: =IFERROR("3. "&INDEX(LIV_Titre,MATCH(LARGE(LIV_Score,3),LIV_Score,0)),"") | AG18: =IFERROR(INDEX(LIV_Total,MATCH(LARGE(LIV_Score,3),LIV_Score,0)),"")
B19: =HYPERLINK("#'Mouvements'!A1","↕ Mouvements de stock") | X19: ● | Y19: =Calculs!E7 | AB19: =Calculs!F7 | AD19: =IFERROR(" "&INDEX(LIV_Auteur,MATCH(LARGE(LIV_Score,3),LIV_Score,0)),"")
B20: =HYPERLINK("#'Recherche'!A1","🔍 Recherche") | X20: ● | Y20: =Calculs!E8 | AB20: =Calculs!F8 | AD20: =IFERROR("4. "&INDEX(LIV_Titre,MATCH(LARGE(LIV_Score,4),LIV_Score,0)),"") | AG20: =IFERROR(INDEX(LIV_Total,MATCH(LARGE(LIV_Score,4),LIV_Score,0)),"")
B21: =HYPERLINK("#'Rapport mensuel'!A1","🖨 Rapport mensuel") | X21: ● | Y21: =Calculs!E9 | AB21: =Calculs!F9 | AD21: =IFERROR(" "&INDEX(LIV_Auteur,MATCH(LARGE(LIV_Score,4),LIV_Score,0)),"")
B22: =HYPERLINK("#'Paramètres'!A1","⚙ Paramètres") | X22: ● | Y22: =Calculs!E10 | AB22: =Calculs!F10 | AD22: =IFERROR("5. "&INDEX(LIV_Titre,MATCH(LARGE(LIV_Score,5),LIV_Score,0)),"") | AG22: =IFERROR(INDEX(LIV_Total,MATCH(LARGE(LIV_Score,5),LIV_Score,0)),"")
Y23: TOTAL | AB23: =SUM(LIV_Ex) | AD23: =IFERROR(" "&INDEX(LIV_Auteur,MATCH(LARGE(LIV_Score,5),LIV_Score,0)),"")
AD25: =HYPERLINK("#'Livres'!E6","Voir le catalogue →")
B30: ☀ Résumé du jour | E30: ⏰ Livres en retard | P30: =HYPERLINK("#'Emprunts'!M6","Voir tout →") | T30: 🕒 Emprunts récents | AE30: =HYPERLINK("#'Emprunts'!E6","Voir tout →")
B31: Emprunts aujourd'hui | C31: =COUNTIF(EMP_Date,TODAY()) | E31: LIVRE | J31: MEMBRE | N31: PRÉVU LE | Q31: RETARD | T31: DATE | V31: MEMBRE | Z31: LIVRE | AE31: STATUT
B32: Retours aujourd'hui | C32: =COUNTIF(EMP_Retour,TODAY()) | E32: =IFERROR(INDEX(EMP_Titre,MATCH(LARGE(EMP_ScoreRetard,1),EMP_ScoreRetard,0)),"") | J32: =IFERROR(INDEX(EMP_Nom,MATCH(LARGE(EMP_ScoreRetard,1),EMP_ScoreRetard,0)),"") | N32: =IFERROR(INDEX(EMP_Prevu,MATCH(LARGE(EMP_ScoreRetard,1),EMP_ScoreRetard,0)),"") | Q32: =IFERROR(INDEX(EMP_Jours,MATCH(LARGE(EMP_ScoreRetard,1),EMP_ScoreRetard,0)),"") | T32: =IFERROR(INDEX(EMP_Date,MATCH(LARGE(EMP_ScoreRecent,1),EMP_ScoreRecent,0)),"") | V32: =IFERROR(INDEX(EMP_Nom,MATCH(LARGE(EMP_ScoreRecent,1),EMP_ScoreRecent,0)),"") | Z32: =IFERROR(INDEX(EMP_Titre,MATCH(LARGE(EMP_ScoreRecent,1),EMP_ScoreRecent,0)),"") | AE32: =IFERROR(INDEX(EMP_Statut,MATCH(LARGE(EMP_ScoreRecent,1),EMP_ScoreRecent,0)),"")
B33: À rendre aujourd'hui | C33: =COUNTIFS(EMP_Prevu,TODAY(),EMP_Retour,"") | E33: =IFERROR(INDEX(EMP_Titre,MATCH(LARGE(EMP_ScoreRetard,2),EMP_ScoreRetard,0)),"") | J33: =IFERROR(INDEX(EMP_Nom,MATCH(LARGE(EMP_ScoreRetard,2),EMP_ScoreRetard,0)),"") | N33: =IFERROR(INDEX(EMP_Prevu,MATCH(LARGE(EMP_ScoreRetard,2),EMP_ScoreRetard,0)),"") | Q33: =IFERROR(INDEX(EMP_Jours,MATCH(LARGE(EMP_ScoreRetard,2),EMP_ScoreRetard,0)),"") | T33: =IFERROR(INDEX(EMP_Date,MATCH(LARGE(EMP_ScoreRecent,2),EMP_ScoreRecent,0)),"") | V33: =IFERROR(INDEX(EMP_Nom,MATCH(LARGE(EMP_ScoreRecent,2),EMP_ScoreRecent,0)),"") | Z33: =IFERROR(INDEX(EMP_Titre,MATCH(LARGE(EMP_ScoreRecent,2),EMP_ScoreRecent,0)),"") | AE33: =IFERROR(INDEX(EMP_Statut,MATCH(LARGE(EMP_ScoreRecent,2),EMP_ScoreRecent,0)),"")
B34: Nouveaux membres (mois) | C34: =COUNTIFS(MEM_Insc,">="&DATE(YEAR(TODAY()),MONTH(TODAY()),1)) | E34: =IFERROR(INDEX(EMP_Titre,MATCH(LARGE(EMP_ScoreRetard,3),EMP_ScoreRetard,0)),"") | J34: =IFERROR(INDEX(EMP_Nom,MATCH(LARGE(EMP_ScoreRetard,3),EMP_ScoreRetard,0)),"") | N34: =IFERROR(INDEX(EMP_Prevu,MATCH(LARGE(EMP_ScoreRetard,3),EMP_ScoreRetard,0)),"") | Q34: =IFERROR(INDEX(EMP_Jours,MATCH(LARGE(EMP_ScoreRetard,3),EMP_ScoreRetard,0)),"") | T34: =IFERROR(INDEX(EMP_Date,MATCH(LARGE(EMP_ScoreRecent,3),EMP_ScoreRecent,0)),"") | V34: =IFERROR(INDEX(EMP_Nom,MATCH(LARGE(EMP_ScoreRecent,3),EMP_ScoreRecent,0)),"") | Z34: =IFERROR(INDEX(EMP_Titre,MATCH(LARGE(EMP_ScoreRecent,3),EMP_ScoreRecent,0)),"") | AE34: =IFERROR(INDEX(EMP_Statut,MATCH(LARGE(EMP_ScoreRecent,3),EMP_ScoreRecent,0)),"")
B35: Livres en retard | C35: =COUNTIF(EMP_Statut,"En retard") | E35: =IFERROR(INDEX(EMP_Titre,MATCH(LARGE(EMP_ScoreRetard,4),EMP_ScoreRetard,0)),"") | J35: =IFERROR(INDEX(EMP_Nom,MATCH(LARGE(EMP_ScoreRetard,4),EMP_ScoreRetard,0)),"") | N35: =IFERROR(INDEX(EMP_Prevu,MATCH(LARGE(EMP_ScoreRetard,4),EMP_ScoreRetard,0)),"") | Q35: =IFERROR(INDEX(EMP_Jours,MATCH(LARGE(EMP_ScoreRetard,4),EMP_ScoreRetard,0)),"") | T35: =IFERROR(INDEX(EMP_Date,MATCH(LARGE(EMP_ScoreRecent,4),EMP_ScoreRecent,0)),"") | V35: =IFERROR(INDEX(EMP_Nom,MATCH(LARGE(EMP_ScoreRecent,4),EMP_ScoreRecent,0)),"") | Z35: =IFERROR(INDEX(EMP_Titre,MATCH(LARGE(EMP_ScoreRecent,4),EMP_ScoreRecent,0)),"") | AE35: =IFERROR(INDEX(EMP_Statut,MATCH(LARGE(EMP_ScoreRecent,4),EMP_ScoreRecent,0)),"")
B36: Amendes à encaisser | C36: =SUMIFS(EMP_Amende,EMP_Paye,"<>Oui") | E36: =IFERROR(INDEX(EMP_Titre,MATCH(LARGE(EMP_ScoreRetard,5),EMP_ScoreRetard,0)),"") | J36: =IFERROR(INDEX(EMP_Nom,MATCH(LARGE(EMP_ScoreRetard,5),EMP_ScoreRetard,0)),"") | N36: =IFERROR(INDEX(EMP_Prevu,MATCH(LARGE(EMP_ScoreRetard,5),EMP_ScoreRetard,0)),"") | Q36: =IFERROR(INDEX(EMP_Jours,MATCH(LARGE(EMP_ScoreRetard,5),EMP_ScoreRetard,0)),"") | T36: =IFERROR(INDEX(EMP_Date,MATCH(LARGE(EMP_ScoreRecent,5),EMP_ScoreRecent,0)),"") | V36: =IFERROR(INDEX(EMP_Nom,MATCH(LARGE(EMP_ScoreRecent,5),EMP_ScoreRecent,0)),"") | Z36: =IFERROR(INDEX(EMP_Titre,MATCH(LARGE(EMP_ScoreRecent,5),EMP_ScoreRecent,0)),"") | AE36: =IFERROR(INDEX(EMP_Statut,MATCH(LARGE(EMP_ScoreRecent,5),EMP_ScoreRecent,0)),"")
E39: 📦 Fournitures en alerte | P39: =HYPERLINK("#'Fournitures'!E6","Voir le stock →") | T39: État des stocks de fournitures | AD39: ⚡ Actions rapides
E40: ARTICLE | J40: UNITÉ | L40: STOCK | N40: SEUIL MIN. | Q40: STATUT
E41: =IFERROR(INDEX(FOU_Article,MATCH(SMALL(FOU_Score,1),FOU_Score,0)),"") | J41: =IFERROR(INDEX(FOU_Unite,MATCH(SMALL(FOU_Score,1),FOU_Score,0)),"") | L41: =IFERROR(INDEX(FOU_Stock,MATCH(SMALL(FOU_Score,1),FOU_Score,0)),"") | N41: =IFERROR(INDEX(FOU_Seuil,MATCH(SMALL(FOU_Score,1),FOU_Score,0)),"") | Q41: =IFERROR(INDEX(FOU_Statut,MATCH(SMALL(FOU_Score,1),FOU_Score,0)),"") | AD41: =HYPERLINK("#'Emprunts'!F"&(7+COUNTIF(EMP_Date,">0")),"＋ Nouvel emprunt")
E42: =IFERROR(INDEX(FOU_Article,MATCH(SMALL(FOU_Score,2),FOU_Score,0)),"") | J42: =IFERROR(INDEX(FOU_Unite,MATCH(SMALL(FOU_Score,2),FOU_Score,0)),"") | L42: =IFERROR(INDEX(FOU_Stock,MATCH(SMALL(FOU_Score,2),FOU_Score,0)),"") | N42: =IFERROR(INDEX(FOU_Seuil,MATCH(SMALL(FOU_Score,2),FOU_Score,0)),"") | Q42: =IFERROR(INDEX(FOU_Statut,MATCH(SMALL(FOU_Score,2),FOU_Score,0)),"") | X42: ● | Y42: ="En stock" | AB42: =Calculs!I2 | AD42: =HYPERLINK("#'Emprunts'!L"&IFERROR(MATCH("",EMP_Retour,0)+6,7),"↩ Enregistrer un retour")
E43: =IFERROR(INDEX(FOU_Article,MATCH(SMALL(FOU_Score,3),FOU_Score,0)),"") | J43: =IFERROR(INDEX(FOU_Unite,MATCH(SMALL(FOU_Score,3),FOU_Score,0)),"") | L43: =IFERROR(INDEX(FOU_Stock,MATCH(SMALL(FOU_Score,3),FOU_Score,0)),"") | N43: =IFERROR(INDEX(FOU_Seuil,MATCH(SMALL(FOU_Score,3),FOU_Score,0)),"") | Q43: =IFERROR(INDEX(FOU_Statut,MATCH(SMALL(FOU_Score,3),FOU_Score,0)),"") | X43: ● | Y43: ="Stock faible" | AB43: =Calculs!I3 | AD43: =HYPERLINK("#'Livres'!E"&(7+COUNTIF(LIV_Code,"?*")),"＋ Nouveau livre")
E44: =IFERROR(INDEX(FOU_Article,MATCH(SMALL(FOU_Score,4),FOU_Score,0)),"") | J44: =IFERROR(INDEX(FOU_Unite,MATCH(SMALL(FOU_Score,4),FOU_Score,0)),"") | L44: =IFERROR(INDEX(FOU_Stock,MATCH(SMALL(FOU_Score,4),FOU_Score,0)),"") | N44: =IFERROR(INDEX(FOU_Seuil,MATCH(SMALL(FOU_Score,4),FOU_Score,0)),"") | Q44: =IFERROR(INDEX(FOU_Statut,MATCH(SMALL(FOU_Score,4),FOU_Score,0)),"") | X44: ● | Y44: ="Rupture" | AB44: =Calculs!I4 | AD44: =HYPERLINK("#'Membres'!E"&(7+COUNTIF(MEM_ID,"?*")),"＋ Nouveau membre")
E45: =IFERROR(INDEX(FOU_Article,MATCH(SMALL(FOU_Score,5),FOU_Score,0)),"") | J45: =IFERROR(INDEX(FOU_Unite,MATCH(SMALL(FOU_Score,5),FOU_Score,0)),"") | L45: =IFERROR(INDEX(FOU_Stock,MATCH(SMALL(FOU_Score,5),FOU_Score,0)),"") | N45: =IFERROR(INDEX(FOU_Seuil,MATCH(SMALL(FOU_Score,5),FOU_Score,0)),"") | Q45: =IFERROR(INDEX(FOU_Statut,MATCH(SMALL(FOU_Score,5),FOU_Score,0)),"") | Y45: TOTAL ARTICLES | AB45: =COUNTIF(FOU_Code,"?*") | AD45: =HYPERLINK("#'Mouvements'!F"&(7+COUNTIF(MOV_Date,">0")),"↕ Mouvement de stock")
E46: =IFERROR(INDEX(FOU_Article,MATCH(SMALL(FOU_Score,6),FOU_Score,0)),"") | J46: =IFERROR(INDEX(FOU_Unite,MATCH(SMALL(FOU_Score,6),FOU_Score,0)),"") | L46: =IFERROR(INDEX(FOU_Stock,MATCH(SMALL(FOU_Score,6),FOU_Score,0)),"") | N46: =IFERROR(INDEX(FOU_Seuil,MATCH(SMALL(FOU_Score,6),FOU_Score,0)),"") | Q46: =IFERROR(INDEX(FOU_Statut,MATCH(SMALL(FOU_Score,6),FOU_Score,0)),"") | AD46: =HYPERLINK("#'Recherche'!F5","🔍 Rechercher")
B50: Made by Alexandre Declaire | E50: ="Bibliothèque "&P_Ecole&" · Les chiffres se mettent à jour automatiquement à partir des feuilles de données."

Sheet Livres
E2: 📚 Catalogue des livres | N2: =HYPERLINK("#'Tableau de bord'!A1","⌂ Tableau de bord") | P2: =HYPERLINK("#'Livres'!E"&(7+COUNTIF(LIV_Code,"?*")),"＋ Nouveau livre")
E3: Saisissez dans les colonnes blanches — les colonnes bleutées se calculent automatiquement.
E4: =COUNTIF(LIV_Code,"?*")&" titres" | G4: =SUM(LIV_Ex)&" exemplaires" | I4: =SUM(LIV_Dispo)&" disponibles" | K4: =SUM(LIV_Emp)&" empruntés"
E6: Code | F6: ISBN | G6: Titre | H6: Auteur | I6: Catégorie | J6: Éditeur | K6: Année | L6: Exemplaires | M6: Emplacement | N6: Empruntés | O6: Disponibles | P6: Total emprunts | Q6: Statut
E7: LIV-001 | F7: 978-2-2824-1409-4 | G7: L'Enfant noir | H7: Camara Laye | I7: Littérature africaine | J7: Plon | K7: 1953 | L7: 4 | M7: Rayon B2 | N7: =IF($E7="","",COUNTIFS(EMP_Livre,$E7,EMP_Retour,"")) | O7: =IF($E7="","",$L7-$N7) | P7: =IF($E7="","",COUNTIF(EMP_Livre,$E7)) | Q7: =IF($E7="","",IF($O7<=0,"Indisponible",IF(AND($O7=1,$L7>1),"Dernier exemplaire","Disponible"))) | S7: =IF($E7="","",$P7+ROW()/100000) | T7: =IF(OR(Q_Rech="",$E7=""),"",IF(ISNUMBER(SEARCH(Q_Rech,$E7&" "&$F7&" "&$G7&" "&$H7&" "&$I7)),COUNT($T$6:$T6)+1,"")) | U7: =IF($E7="","",IF(COUNTIFS(EMP_Livre,$E7,EMP_Date,">="&R_Mois,EMP_Date,"<"&EDATE(R_Mois,1))=0,"",COUNTIFS(EMP_Livre,$E7,EMP_Date,">="&R_Mois,EMP_Date,"<"&EDATE(R_Mois,1))+ROW()/100000))
B8: =HYPERLINK("#'Tableau de bord'!A1","▦ Tableau de bord") | E8: LIV-002 | F8: 978-2-3286-2679-8 | G8: Une si longue lettre | H8: Mariama Bâ | I8: Littérature africaine | J8: NEA | K8: 1979 | L8: 3 | M8: Rayon B4 | N8: =IF($E8="","",COUNTIFS(EMP_Livre,$E8,EMP_Retour,"")) | O8: =IF($E8="","",$L8-$N8) | P8: =IF($E8="","",COUNTIF(EMP_Livre,$E8)) | Q8: =IF($E8="","",IF($O8<=0,"Indisponible",IF(AND($O8=1,$L8>1),"Dernier exemplaire","Disponible"))) | S8: =IF($E8="","",$P8+ROW()/100000) | T8: =IF(OR(Q_Rech="",$E8=""),"",IF(ISNUMBER(SEARCH(Q_Rech,$E8&" "&$F8&" "&$G8&" "&$H8&" "&$I8)),COUNT($T$6:$T7)+1,"")) | U8: =IF($E8="","",IF(COUNTIFS(EMP_Livre,$E8,EMP_Date,">="&R_Mois,EMP_Date,"<"&EDATE(R_Mois,1))=0,"",COUNTIFS(EMP_Livre,$E8,EMP_Date,">="&R_Mois,EMP_Date,"<"&EDATE(R_Mois,1))+ROW()/100000))
B9: =HYPERLINK("#'Livres'!A1","📚 Livres") | E9: LIV-003 | F9: 978-2-1520-1488-1 | G9: Le Vieux Nègre et la médaille | H9: Ferdinand Oyono | I9: Littérature africaine | J9: Julliard | K9: 1956 | L9: 2 | M9: Rayon B2 | N9: =IF($E9="","",COUNTIFS(EMP_Livre,$E9,EMP_Retour,"")) | O9: =IF($E9="","",$L9-$N9) | P9: =IF($E9="","",COUNTIF(EMP_Livre,$E9)) | Q9: =IF($E9="","",IF($O9<=0,"Indisponible",IF(AND($O9=1,$L9>1),"Dernier exemplaire","Disponible"))) | S9: =IF($E9="","",$P9+ROW()/100000) | T9: =IF(OR(Q_Rech="",$E9=""),"",IF(ISNUMBER(SEARCH(Q_Rech,$E9&" "&$F9&" "&$G9&" "&$H9&" "&$I9)),COUNT($T$6:$T8)+1,"")) | U9: =IF($E9="","",IF(COUNTIFS(EMP_Livre,$E9,EMP_Date,">="&R_Mois,EMP_Date,"<"&EDATE(R_Mois,1))=0,"",COUNTIFS(EMP_Livre,$E9,EMP_Date,">="&R_Mois,EMP_Date,"<"&EDATE(R_Mois,1))+ROW()/100000))
B10: =HYPERLINK("#'Membres'!A1","👥 Membres") | E10: LIV-004 | F10: 978-2-9279-1434-8 | G10: Les Soleils des indépendances | H10: Ahmadou Kourouma | I10: Littérature africaine | J10: Seuil | K10: 1968 | L10: 4 | M10: Rayon B4 | N10: =IF($E10="","",COUNTIFS(EMP_Livre,$E10,EMP_Retour,"")) | O10: =IF($E10="","",$L10-$N10) | P10: =IF($E10="","",COUNTIF(EMP_Livre,$E10)) | Q10: =IF($E10="","",IF($O10<=0,"Indisponible",IF(AND($O10=1,$L10>1),"Dernier exemplaire","Disponible"))) | S10: =IF($E10="","",$P10+ROW()/100000) | T10: =IF(OR(Q_Rech="",$E10=""),"",IF(ISNUMBER(SEARCH(Q_Rech,$E10&" "&$F10&" "&$G10&" "&$H10&" "&$I10)),COUNT($T$6:$T9)+1,"")) | U10: =IF($E10="","",IF(COUNTIFS(EMP_Livre,$E10,EMP_Date,">="&R_Mois,EMP_Date,"<"&EDATE(R_Mois,1))=0,"",COUNTIFS(EMP_Livre,$E10,EMP_Date,">="&R_Mois,EMP_Date,"<"&EDATE(R_Mois,1))+ROW()/100000))
B11: =HYPERLINK("#'Emprunts'!A1","🔄 Emprunts") | E11: LIV-005 | F11: 978-2-4611-8359-9 | G11: Things Fall Apart | H11: Chinua Achebe | I11: Littérature africaine | J11: Heinemann | K11: 1958 | L11: 2 | M11: Rayon B1 | N11: =IF($E11="","",COUNTIFS(EMP_Livre,$E11,EMP_Retour,"")) | O11: =IF($E11="","",$L11-$N11) | P11: =IF($E11="","",COUNTIF(EMP_Livre,$E11)) | Q11: =IF($E11="","",IF($O11<=0,"Indisponible",IF(AND($O11=1,$L11>1),"Dernier exemplaire","Disponible"))) | S11: =IF($E11="","",$P11+ROW()/100000) | T11: =IF(OR(Q_Rech="",$E11=""),"",IF(ISNUMBER(SEARCH(Q_Rech,$E11&" "&$F11&" "&$G11&" "&$H11&" "&$I11)),COUNT($T$6:$T10)+1,"")) | U11: =IF($E11="","",IF(COUNTIFS(EMP_Livre,$E11,EMP_Date,">="&R_Mois,EMP_Date,"<"&EDATE(R_Mois,1))=0,"",COUNTIFS(EMP_Livre,$E11,EMP_Date,">="&R_Mois,EMP_Date,"<"&EDATE(R_Mois,1))+ROW()/100000))
B12: =HYPERLINK("#'Fournitures'!A1","📦 Fournitures") | E12: LIV-006 | F12: 978-2-3615-7924-5 | G12: Ville cruelle | H12: Mongo Beti | I12: Littérature africaine | J12: Présence Africaine | K12: 1954 | L12: 2 | M12: Rayon B2 | N12: =IF($E12="","",COUNTIFS(EMP_Livre,$E12,EMP_Retour,"")) | O12: =IF($E12="","",$L12-$N12) | P12: =IF($E12="","",COUNTIF(EMP_Livre,$E12)) | Q12: =IF($E12="","",IF($O12<=0,"Indisponible",IF(AND($O12=1,$L12>1),"Dernier exemplaire","Disponible"))) | S12: =IF($E12="","",$P12+ROW()/100000) | T12: =IF(OR(Q_Rech="",$E12=""),"",IF(ISNUMBER(SEARCH(Q_Rech,$E12&" "&$F12&" "&$G12&" "&$H12&" "&$I12)),COUNT($T$6:$T11)+1,"")) | U12: =IF($E12="","",IF(COUNTIFS(EMP_Livre,$E12,EMP_Date,">="&R_Mois,EMP_Date,"<"&EDATE(R_Mois,1))=0,"",COUNTIFS(EMP_Livre,$E12,EMP_Date,">="&R_Mois,EMP_Date,"<"&EDATE(R_Mois,1))+ROW()/100000))
B13: =HYPERLINK("#'Mouvements'!A1","↕ Mouvements de stock") | E13: LIV-007 | F13: 978-2-4527-6514-1 | G13: Le Pleurer-Rire | H13: Henri Lopes | I13: Littérature africaine | J13: Présence Africaine | K13: 1982 | L13: 1 | M13: Rayon B4 | N13: =IF($E13="","",COUNTIFS(EMP_Livre,$E13,EMP_Retour,"")) | O13: =IF($E13="","",$L13-$N13) | P13: =IF($E13="","",COUNTIF(EMP_Livre,$E13)) | Q13: =IF($E13="","",IF($O13<=0,"Indisponible",IF(AND($O13=1,$L13>1),"Dernier exemplaire","Disponible"))) | S13: =IF($E13="","",$P13+ROW()/100000) | T13: =IF(OR(Q_Rech="",$E13=""),"",IF(ISNUMBER(SEARCH(Q_Rech,$E13&" "&$F13&" "&$G13&" "&$H13&" "&$I13)),COUNT($T$6:$T12)+1,"")) | U13: =IF($E13="","",IF(COUNTIFS(EMP_Livre,$E13,EMP_Date,">="&R_Mois,EMP_Date,"<"&EDATE(R_Mois,1))=0,"",COUNTIFS(EMP_Livre,$E13,EMP_Date,">="&R_Mois,EMP_Date,"<"&EDATE(R_Mois,1))+ROW()/100000))
B14: =HYPERLINK("#'Recherche'!A1","🔍 Recherche") | E14: LIV-008 | F14: 978-2-2584-6881-5 | G14: Allah n'est pas obligé | H14: Ahmadou Kourouma | I14: Littérature africaine | J14: Seuil | K14: 2000 | L14: 3 | M14: Rayon B3 | N14: =IF($E14="","",COUNTIFS(EMP_Livre,$E14,EMP_Retour,"")) | O14: =IF($E14="","",$L14-$N14) | P14: =IF($E14="","",COUNTIF(EMP_Livre,$E14)) | Q14: =IF($E14="","",IF($O14<=0,"Indisponible",IF(AND($O14=1,$L14>1),"Dernier exemplaire","Disponible"))) | S14: =IF($E14="","",$P14+ROW()/100000) | T14: =IF(OR(Q_Rech="",$E14=""),"",IF(ISNUMBER(SEARCH(Q_Rech,$E14&" "&$F14&" "&$G14&" "&$H14&" "&$I14)),COUNT($T$6:$T13)+1,"")) | U14: =IF($E14="","",IF(COUNTIFS(EMP_Livre,$E14,EMP_Date,">="&R_Mois,EMP_Date,"<"&EDATE(R_Mois,1))=0,"",COUNTIFS(EMP_Livre,$E14,EMP_Date,">="&R_Mois,EMP_Date,"<"&EDATE(R_Mois,1))+ROW()/100000))
B15: =HYPERLINK("#'Rapport mensuel'!A1","🖨 Rapport mensuel") | E15: LIV-009 | F15: 978-2-1711-8527-8 | G15: Les Bouts de bois de Dieu | H15: Sembène Ousmane | I15: Littérature africaine | J15: Pocket | K15: 1960 | L15: 1 | M15: Rayon B4 | N15: =IF($E15="","",COUNTIFS(EMP_Livre,$E15,EMP_Retour,"")) | O15: =IF($E15="","",$L15-$N15) | P15: =IF($E15="","",COUNTIF(EMP_Livre,$E15)) | Q15: =IF($E15="","",IF($O15<=0,"Indisponible",IF(AND($O15=1,$L15>1),"Dernier exemplaire","Disponible"))) | S15: =IF($E15="","",$P15+ROW()/100000) | T15: =IF(OR(Q_Rech="",$E15=""),"",IF(ISNUMBER(SEARCH(Q_Rech,$E15&" "&$F15&" "&$G15&" "&$H15&" "&$I15)),COUNT($T$6:$T14)+1,"")) | U15: =IF($E15="","",IF(COUNTIFS(EMP_Livre,$E15,EMP_Date,">="&R_Mois,EMP_Date,"<"&EDATE(R_Mois,1))=0,"",COUNTIFS(EMP_Livre,$E15,EMP_Date,">="&R_Mois,EMP_Date,"<"&EDATE(R_Mois,1))+ROW()/100000))
B16: =HYPERLINK("#'Paramètres'!A1","⚙ Paramètres") | E16: LIV-010 | F16: 978-2-2291-5803-9 | G16: Petit Pays | H16: Gaël Faye | I16: Littérature africaine | J16: Grasset | K16: 2016 | L16: 5 | M16: Rayon B2 | N16: =IF($E16="","",COUNTIFS(EMP_Livre,$E16,EMP_Retour,"")) | O16: =IF($E16="","",$L16-$N16) | P16: =IF($E16="","",COUNTIF(EMP_Livre,$E16)) | Q16: =IF($E16="","",IF($O16<=0,"Indisponible",IF(AND($O16=1,$L16>1),"Dernier exemplaire","Disponible"))) | S16: =IF($E16="","",$P16+ROW()/100000) | T16: =IF(OR(Q_Rech="",$E16=""),"",IF(ISNUMBER(SEARCH(Q_Rech,$E16&" "&$F16&" "&$G16&" "&$H16&" "&$I16)),COUNT($T$6:$T15)+1,"")) | U16: =IF($E16="","",IF(COUNTIFS(EMP_Livre,$E16,EMP_Date,">="&R_Mois,EMP_Date,"<"&EDATE(R_Mois,1))=0,"",COUNTIFS(EMP_Livre,$E16,EMP_Date,">="&R_Mois,EMP_Date,"<"&EDATE(R_Mois,1))+ROW()/100000))
E17: LIV-011 | F17: 978-2-2139-1750-3 | G17: Le Petit Prince | H17: Antoine de Saint-Exupéry | I17: Jeunesse | J17: Gallimard | K17: 1943 | L17: 5 | M17: Rayon H1 | N17: =IF($E17="","",COUNTIFS(EMP_Livre,$E17,EMP_Retour,"")) | O17: =IF($E17="","",$L17-$N17) | P17: =IF($E17="","",COUNTIF(EMP_Livre,$E17)) | Q17: =IF($E17="","",IF($O17<=0,"Indisponible",IF(AND($O17=1,$L17>1),"Dernier exemplaire","Disponible"))) | S17: =IF($E17="","",$P17+ROW()/100000) | T17: =IF(OR(Q_Rech="",$E17=""),"",IF(ISNUMBER(SEARCH(Q_Rech,$E17&" "&$F17&" "&$G17&" "&$H17&" "&$I17)),COUNT($T$6:$T16)+1,"")) | U17: =IF($E17="","",IF(COUNTIFS(EMP_Livre,$E17,EMP_Date,">="&R_Mois,EMP_Date,"<"&EDATE(R_Mois,1))=0,"",COUNTIFS(EMP_Livre,$E17,EMP_Date,">="&R_Mois,EMP_Date,"<"&EDATE(R_Mois,1))+ROW()/100000))
E18: LIV-012 | F18: 978-2-4814-2654-6 | G18: Les Misérables | H18: Victor Hugo | I18: Roman | J18: Folio | K18: 1862 | L18: 2 | M18: Rayon A4 | N18: =IF($E18="","",COUNTIFS(EMP_Livre,$E18,EMP_Retour,"")) | O18: =IF($E18="","",$L18-$N18) | P18: =IF($E18="","",COUNTIF(EMP_Livre,$E18)) | Q18: =IF($E18="","",IF($O18<=0,"Indisponible",IF(AND($O18=1,$L18>1),"Dernier exemplaire","Disponible"))) | S18: =IF($E18="","",$P18+ROW()/100000) | T18: =IF(OR(Q_Rech="",$E18=""),"",IF(ISNUMBER(SEARCH(Q_Rech,$E18&" "&$F18&" "&$G18&" "&$H18&" "&$I18)),COUNT($T$6:$T17)+1,"")) | U18: =IF($E18="","",IF(COUNTIFS(EMP_Livre,$E18,EMP_Date,">="&R_Mois,EMP_Date,"<"&EDATE(R_Mois,1))=0,"",COUNTIFS(EMP_Livre,$E18,EMP_Date,">="&R_Mois,EMP_Date,"<"&EDATE(R_Mois,1))+ROW()/100000))
E19: LIV-013 | F19: 978-2-6977-3664-5 | G19: Germinal | H19: Émile Zola | I19: Roman | J19: Folio | K19: 1885 | L19: 2 | M19: Rayon A2 | N19: =IF($E19="","",COUNTIFS(EMP_Livre,$E19,EMP_Retour,"")) | O19: =IF($E19="","",$L19-$N19) | P19: =IF($E19="","",COUNTIF(EMP_Livre,$E19)) | Q19: =IF($E19="","",IF($O19<=0,"Indisponible",IF(AND($O19=1,$L19>1),"Dernier exemplaire","Disponible"))) | S19: =IF($E19="","",$P19+ROW()/100000) | T19: =IF(OR(Q_Rech="",$E19=""),"",IF(ISNUMBER(SEARCH(Q_Rech,$E19&" "&$F19&" "&$G19&" "&$H19&" "&$I19)),COUNT($T$6:$T18)+1,"")) | U19: =IF($E19="","",IF(COUNTIFS(EMP_Livre,$E19,EMP_Date,">="&R_Mois,EMP_Date,"<"&EDATE(R_Mois,1))=0,"",COUNTIFS(EMP_Livre,$E19,EMP_Date,">="&R_Mois,EMP_Date,"<"&EDATE(R_Mois,1))+ROW()/100000))
E20: LIV-014 | F20: 978-2-5374-2169-9 | G20: L'Étranger | H20: Albert Camus | I20: Roman | J20: Folio | K20: 1942 | L20: 4 | M20: Rayon A2 | N20: =IF($E20="","",COUNTIFS(EMP_Livre,$E20,EMP_Retour,"")) | O20: =IF($E20="","",$L20-$N20) | P20: =IF($E20="","",COUNTIF(EMP_Livre,$E20)) | Q20: =IF($E20="","",IF($O20<=0,"Indisponible",IF(AND($O20=1,$L20>1),"Dernier exemplaire","Disponible"))) | S20: =IF($E20="","",$P20+ROW()/100000) | T20: =IF(OR(Q_Rech="",$E20=""),"",IF(ISNUMBER(SEARCH(Q_Rech,$E20&" "&$F20&" "&$G20&" "&$H20&" "&$I20)),COUNT($T$6:$T19)+1,"")) | U20: =IF($E20="","",IF(COUNTIFS(EMP_Livre,$E20,EMP_Date,">="&R_Mois,EMP_Date,"<"&EDATE(R_Mois,1))=0,"",COUNTIFS(EMP_Livre,$E20,EMP_Date,">="&R_Mois,EMP_Date,"<"&EDATE(R_Mois,1))+ROW()/100000))
E21: LIV-015 | F21: 978-2-3677-8573-6 | G21: Candide | H21: Voltaire | I21: Roman | J21: Librio | K21: 1759 | L21: 2 | M21: Rayon A2 | N21: =IF($E21="","",COUNTIFS(EMP_Livre,$E21,EMP_Retour,"")) | O21: =IF($E21="","",$L21-$N21) | P21: =IF($E21="","",COUNTIF(EMP_Livre,$E21)) | Q21: =IF($E21="","",IF($O21<=0,"Indisponible",IF(AND($O21=1,$L21>1),"Dernier exemplaire","Disponible"))) | S21: =IF($E21="","",$P21+ROW()/100000) | T21: =IF(OR(Q_Rech="",$E21=""),"",IF(ISNUMBER(SEARCH(Q_Rech,$E21&" "&$F21&" "&$G21&" "&$H21&" "&$I21)),COUNT($T$6:$T20)+1,"")) | U21: =IF($E21="","",IF(COUNTIFS(EMP_Livre,$E21,EMP_Date,">="&R_Mois,EMP_Date,"<"&EDATE(R_Mois,1))=0,"",COUNTIFS(EMP_Livre,$E21,EMP_Date,">="&R_Mois,EMP_Date,"<"&EDATE(R_Mois,1))+ROW()/100000))
E22: LIV-016 | F22: 978-2-6313-1916-3 | G22: Vingt mille lieues sous les mers | H22: Jules Verne | I22: Roman | J22: Hetzel | K22: 1870 | L22: 1 | M22: Rayon A3 | N22: =IF($E22="","",COUNTIFS(EMP_Livre,$E22,EMP_Retour,"")) | O22: =IF($E22="","",$L22-$N22) | P22: =IF($E22="","",COUNTIF(EMP_Livre,$E22)) | Q22: =IF($E22="","",IF($O22<=0,"Indisponible",IF(AND($O22=1,$L22>1),"Dernier exemplaire","Disponible"))) | S22: =IF($E22="","",$P22+ROW()/100000) | T22: =IF(OR(Q_Rech="",$E22=""),"",IF(ISNUMBER(SEARCH(Q_Rech,$E22&" "&$F22&" "&$G22&" "&$H22&" "&$I22)),COUNT($T$6:$T21)+1,"")) | U22: =IF($E22="","",IF(COUNTIFS(EMP_Livre,$E22,EMP_Date,">="&R_Mois,EMP_Date,"<"&EDATE(R_Mois,1))=0,"",COUNTIFS(EMP_Livre,$E22,EMP_Date,">="&R_Mois,EMP_Date,"<"&EDATE(R_Mois,1))+ROW()/100000))
E23: LIV-017 | F23: 978-2-7572-5386-1 | G23: Le Tour du monde en 80 jours | H23: Jules Verne | I23: Roman | J23: Hetzel | K23: 1872 | L23: 2 | M23: Rayon A3 | N23: =IF($E23="","",COUNTIFS(EMP_Livre,$E23,EMP_Retour,"")) | O23: =IF($E23="","",$L23-$N23) | P23: =IF($E23="","",COUNTIF(EMP_Livre,$E23)) | Q23: =IF($E23="","",IF($O23<=0,"Indisponible",IF(AND($O23=1,$L23>1),"Dernier exemplaire","Disponible"))) | S23: =IF($E23="","",$P23+ROW()/100000) | T23: =IF(OR(Q_Rech="",$E23=""),"",IF(ISNUMBER(SEARCH(Q_Rech,$E23&" "&$F23&" "&$G23&" "&$H23&" "&$I23)),COUNT($T$6:$T22)+1,"")) | U23: =IF($E23="","",IF(COUNTIFS(EMP_Livre,$E23,EMP_Date,">="&R_Mois,EMP_Date,"<"&EDATE(R_Mois,1))=0,"",COUNTIFS(EMP_Livre,$E23,EMP_Date,">="&R_Mois,EMP_Date,"<"&EDATE(R_Mois,1))+ROW()/100000))
E24: LIV-018 | F24: 978-2-4483-9179-6 | G24: Antigone | H24: Jean Anouilh | I24: Roman | J24: La Table Ronde | K24: 1944 | L24: 4 | M24: Rayon A4 | N24: =IF($E24="","",COUNTIFS(EMP_Livre,$E24,EMP_Retour,"")) | O24: =IF($E24="","",$L24-$N24) | P24: =IF($E24="","",COUNTIF(EMP_Livre,$E24)) | Q24: =IF($E24="","",IF($O24<=0,"Indisponible",IF(AND($O24=1,$L24>1),"Dernier exemplaire","Disponible"))) | S24: =IF($E24="","",$P24+ROW()/100000) | T24: =IF(OR(Q_Rech="",$E24=""),"",IF(ISNUMBER(SEARCH(Q_Rech,$E24&" "&$F24&" "&$G24&" "&$H24&" "&$I24)),COUNT($T$6:$T23)+1,"")) | U24: =IF($E24="","",IF(COUNTIFS(EMP_Livre,$E24,EMP_Date,">="&R_Mois,EMP_Date,"<"&EDATE(R_Mois,1))=0,"",COUNTIFS(EMP_Livre,$E24,EMP_Date,">="&R_Mois,EMP_Date,"<"&EDATE(R_Mois,1))+ROW()/100000))
E25: LIV-019 | F25: 978-2-3340-5339-2 | G25: Le Cid | H25: Pierre Corneille | I25: Roman | J25: Larousse | K25: 1637 | L25: 2 | M25: Rayon A3 | N25: =IF($E25="","",COUNTIFS(EMP_Livre,$E25,EMP_Retour,"")) | O25: =IF($E25="","",$L25-$N25) | P25: =IF($E25="","",COUNTIF(EMP_Livre,$E25)) | Q25: =IF($E25="","",IF($O25<=0,"Indisponible",IF(AND($O25=1,$L25>1),"Dernier exemplaire","Disponible"))) | S25: =IF($E25="","",$P25+ROW()/100000) | T25: =IF(OR(Q_Rech="",$E25=""),"",IF(ISNUMBER(SEARCH(Q_Rech,$E25&" "&$F25&" "&$G25&" "&$H25&" "&$I25)),COUNT($T$6:$T24)+1,"")) | U25: =IF($E25="","",IF(COUNTIFS(EMP_Livre,$E25,EMP_Date,">="&R_Mois,EMP_Date,"<"&EDATE(R_Mois,1))=0,"",COUNTIFS(EMP_Livre,$E25,EMP_Date,">="&R_Mois,EMP_Date,"<"&EDATE(R_Mois,1))+ROW()/100000))
E26: LIV-020 | F26: 978-2-8019-7543-5 | G26: Le Malade imaginaire | H26: Molière | I26: Roman | J26: Larousse | K26: 1673 | L26: 2 | M26: Rayon A2 | N26: =IF($E26="","",COUNTIFS(EMP_Livre,$E26,EMP_Retour,"")) | O26: =IF($E26="","",$L26-$N26) | P26: =IF($E26="","",COUNTIF(EMP_Livre,$E26)) | Q26: =IF($E26="","",IF($O26<=0,"Indisponible",IF(AND($O26=1,$L26>1),"Dernier exemplaire","Disponible"))) | S26: =IF($E26="","",$P26+ROW()/100000) | T26: =IF(OR(Q_Rech="",$E26=""),"",IF(ISNUMBER(SEARCH(Q_Rech,$E26&" "&$F26&" "&$G26&" "&$H26&" "&$I26)),COUNT($T$6:$T25)+1,"")) | U26: =IF($E26="","",IF(COUNTIFS(EMP_Livre,$E26,EMP_Date,">="&R_Mois,EMP_Date,"<"&EDATE(R_Mois,1))=0,"",COUNTIFS(EMP_Livre,$E26,EMP_Date,">="&R_Mois,EMP_Date,"<"&EDATE(R_Mois,1))+ROW()/100000))
E27: LIV-021 | F27: 978-2-9348-9085-1 | G27: Le Lion | H27: Joseph Kessel | I27: Roman | J27: Folio | K27: 1958 | L27: 1 | M27: Rayon A1 | N27: =IF($E27="","",COUNTIFS(EMP_Livre,$E27,EMP_Retour,"")) | O27: =IF($E27="","",$L27-$N27) | P27: =IF($E27="","",COUNTIF(EMP_Livre,$E27)) | Q27: =IF($E27="","",IF($O27<=0,"Indisponible",IF(AND($O27=1,$L27>1),"Dernier exemplaire","Disponible"))) | S27: =IF($E27="","",$P27+ROW()/100000) | T27: =IF(OR(Q_Rech="",$E27=""),"",IF(ISNUMBER(SEARCH(Q_Rech,$E27&" "&$F27&" "&$G27&" "&$H27&" "&$I27)),COUNT($T$6:$T26)+1,"")) | U27: =IF($E27="","",IF(COUNTIFS(EMP_Livre,$E27,EMP_Date,">="&R_Mois,EMP_Date,"<"&EDATE(R_Mois,1))=0,"",COUNTIFS(EMP_Livre,$E27,EMP_Date,">="&R_Mois,EMP_Date,"<"&EDATE(R_Mois,1))+ROW()/100000))
E28: LIV-022 | F28: 978-2-3504-3621-6 | G28: Bel-Ami | H28: Guy de Maupassant | I28: Roman | J28: Folio | K28: 1885 | L28: 3 | M28: Rayon A1 | N28: =IF($E28="","",COUNTIFS(EMP_Livre,$E28,EMP_Retour,"")) | O28: =IF($E28="","",$L28-$N28) | P28: =IF($E28="","",COUNTIF(EMP_Livre,$E28)) | Q28: =IF($E28="","",IF($O28<=0,"Indisponible",IF(AND($O28=1,$L28>1),"Dernier exemplaire","Disponible"))) | S28: =IF($E28="","",$P28+ROW()/100000) | T28: =IF(OR(Q_Rech="",$E28=""),"",IF(ISNUMBER(SEARCH(Q_Rech,$E28&" "&$F28&" "&$G28&" "&$H28&" "&$I28)),COUNT($T$6:$T27)+1,"")) | U28: =IF($E28="","",IF(COUNTIFS(EMP_Livre,$E28,EMP_Date,">="&R_Mois,EMP_Date,"<"&EDATE(R_Mois,1))=0,"",COUNTIFS(EMP_Livre,$E28,EMP_Date,">="&R_Mois,EMP_Date,"<"&EDATE(R_Mois,1))+ROW()/100000))
... E66: LIV-060 | F66: 978-2-9808-4492-8 | G66: Chaka | H66: Thomas Mofolo | I66: Littérature africaine | J66: Gallimard | K66: 1925 | L66: 2 | M66: Rayon B2 | N66: =IF($E66="","",COUNTIFS(EMP_Livre,$E66,EMP_Retour,"")) | O66: =IF($E66="","",$L66-$N66) | P66: =IF($E66="","",COUNTIF(EMP_Livre,$E66)) | Q66: =IF($E66="","",IF($O66<=0,"Indisponible",IF(AND($O66=1,$L66>1),"Dernier exemplaire","Disponible"))) | S66: =IF($E66="","",$P66+ROW()/100000) | T66: =IF(OR(Q_Rech="",$E66=""),"",IF(ISNUMBER(SEARCH(Q_Rech,$E66&" "&$F66&" "&$G66&" "&$H66&" "&$I66)),COUNT($T$6:$T65)+1,"")) | U66: =IF($E66="","",IF(COUNTIFS(EMP_Livre,$E66,EMP_Date,">="&R_Mois,EMP_Date,"<"&EDATE(R_Mois,1))=0,"",COUNTIFS(EMP_Livre,$E66,EMP_Date,">="&R_Mois,EMP_Date,"<"&EDATE(R_Mois,1))+ROW()/100000))
N67: =IF($E67="","",COUNTIFS(EMP_Livre,$E67,EMP_Retour,"")) | O67: =IF($E67="","",$L67-$N67) | P67: =IF($E67="","",COUNTIF(EMP_Livre,$E67)) | Q67: =IF($E67="","",IF($O67<=0,"Indisponible",IF(AND($O67=1,$L67>1),"Dernier exemplaire","Disponible"))) | S67: =IF($E67="","",$P67+ROW()/100000) | T67: =IF(OR(Q_Rech="",$E67=""),"",IF(ISNUMBER(SEARCH(Q_Rech,$E67&" "&$F67&" "&$G67&" "&$H67&" "&$I67)),COUNT($T$6:$T66)+1,"")) | U67: =IF($E67="","",IF(COUNTIFS(EMP_Livre,$E67,EMP_Date,">="&R_Mois,EMP_Date,"<"&EDATE(R_Mois,1))=0,"",COUNTIFS(EMP_Livre,$E67,EMP_Date,">="&R_Mois,EMP_Date,"<"&EDATE(R_Mois,1))+ROW()/100000))
N68: =IF($E68="","",COUNTIFS(EMP_Livre,$E68,EMP_Retour,"")) | O68: =IF($E68="","",$L68-$N68) | P68: =IF($E68="","",COUNTIF(EMP_Livre,$E68)) | Q68: =IF($E68="","",IF($O68<=0,"Indisponible",IF(AND($O68=1,$L68>1),"Dernier exemplaire","Disponible"))) | S68: =IF($E68="","",$P68+ROW()/100000) | T68: =IF(OR(Q_Rech="",$E68=""),"",IF(ISNUMBER(SEARCH(Q_Rech,$E68&" "&$F68&" "&$G68&" "&$H68&" "&$I68)),COUNT($T$6:$T67)+1,"")) | U68: =IF($E68="","",IF(COUNTIFS(EMP_Livre,$E68,EMP_Date,">="&R_Mois,EMP_Date,"<"&EDATE(R_Mois,1))=0,"",COUNTIFS(EMP_Livre,$E68,EMP_Date,">="&R_Mois,EMP_Date,"<"&EDATE(R_Mois,1))+ROW()/100000))
N69: =IF($E69="","",COUNTIFS(EMP_Livre,$E69,EMP_Retour,"")) | O69: =IF($E69="","",$L69-$N69) | P69: =IF($E69="","",COUNTIF(EMP_Livre,$E69)) | Q69: =IF($E69="","",IF($O69<=0,"Indisponible",IF(AND($O69=1,$L69>1),"Dernier exemplaire","Disponible"))) | S69: =IF($E69="","",$P69+ROW()/100000) | T69: =IF(OR(Q_Rech="",$E69=""),"",IF(ISNUMBER(SEARCH(Q_Rech,$E69&" "&$F69&" "&$G69&" "&$H69&" "&$I69)),COUNT($T$6:$T68)+1,"")) | U69: =IF($E69="","",IF(COUNTIFS(EMP_Livre,$E69,EMP_Date,">="&R_Mois,EMP_Date,"<"&EDATE(R_Mois,1))=0,"",COUNTIFS(EMP_Livre,$E69,EMP_Date,">="&R_Mois,EMP_Date,"<"&EDATE(R_Mois,1))+ROW()/100000))
N70: =IF($E70="","",COUNTIFS(EMP_Livre,$E70,EMP_Retour,"")) | O70: =IF($E70="","",$L70-$N70) | P70: =IF($E70="","",COUNTIF(EMP_Livre,$E70)) | Q70: =IF($E70="","",IF($O70<=0,"Indisponible",IF(AND($O70=1,$L70>1),"Dernier exemplaire","Disponible"))) | S70: =IF($E70="","",$P70+ROW()/100000) | T70: =IF(OR(Q_Rech="",$E70=""),"",IF(ISNUMBER(SEARCH(Q_Rech,$E70&" "&$F70&" "&$G70&" "&$H70&" "&$I70)),COUNT($T$6:$T69)+1,"")) | U70: =IF($E70="","",IF(COUNTIFS(EMP_Livre,$E70,EMP_Date,">="&R_Mois,EMP_Date,"<"&EDATE(R_Mois,1))=0,"",COUNTIFS(EMP_Livre,$E70,EMP_Date,">="&R_Mois,EMP_Date,"<"&EDATE(R_Mois,1))+ROW()/100000))
N71: =IF($E71="","",COUNTIFS(EMP_Livre,$E71,EMP_Retour,"")) | O71: =IF($E71="","",$L71-$N71) | P71: =IF($E71="","",COUNTIF(EMP_Livre,$E71)) | Q71: =IF($E71="","",IF($O71<=0,"Indisponible",IF(AND($O71=1,$L71>1),"Dernier exemplaire","Disponible"))) | S71: =IF($E71="","",$P71+ROW()/100000) | T71: =IF(OR(Q_Rech="",$E71=""),"",IF(ISNUMBER(SEARCH(Q_Rech,$E71&" "&$F71&" "&$G71&" "&$H71&" "&$I71)),COUNT($T$6:$T70)+1,"")) | U71: =IF($E71="","",IF(COUNTIFS(EMP_Livre,$E71,EMP_Date,">="&R_Mois,EMP_Date,"<"&EDATE(R_Mois,1))=0,"",COUNTIFS(EMP_Livre,$E71,EMP_Date,">="&R_Mois,EMP_Date,"<"&EDATE(R_Mois,1))+ROW()/100000))
N72: =IF($E72="","",COUNTIFS(EMP_Livre,$E72,EMP_Retour,"")) | O72: =IF($E72="","",$L72-$N72) | P72: =IF($E72="","",COUNTIF(EMP_Livre,$E72)) | Q72: =IF($E72="","",IF($O72<=0,"Indisponible",IF(AND($O72=1,$L72>1),"Dernier exemplaire","Disponible"))) | S72: =IF($E72="","",$P72+ROW()/100000) | T72: =IF(OR(Q_Rech="",$E72=""),"",IF(ISNUMBER(SEARCH(Q_Rech,$E72&" "&$F72&" "&$G72&" "&$H72&" "&$I72)),COUNT($T$6:$T71)+1,"")) | U72: =IF($E72="","",IF(COUNTIFS(EMP_Livre,$E72,EMP_Date,">="&R_Mois,EMP_Date,"<"&EDATE(R_Mois,1))=0,"",COUNTIFS(EMP_Livre,$E72,EMP_Date,">="&R_Mois,EMP_Date,"<"&EDATE(R_Mois,1))+ROW()/100000))
N73: =IF($E73="","",COUNTIFS(EMP_Livre,$E73,EMP_Retour,"")) | O73: =IF($E73="","",$L73-$N73) | P73: =IF($E73="","",COUNTIF(EMP_Livre,$E73)) | Q73: =IF($E73="","",IF($O73<=0,"Indisponible",IF(AND($O73=1,$L73>1),"Dernier exemplaire","Disponible"))) | S73: =IF($E73="","",$P73+ROW()/100000) | T73: =IF(OR(Q_Rech="",$E73=""),"",IF(ISNUMBER(SEARCH(Q_Rech,$E73&" "&$F73&" "&$G73&" "&$H73&" "&$I73)),COUNT($T$6:$T72)+1,"")) | U73: =IF($E73="","",IF(COUNTIFS(EMP_Livre,$E73,EMP_Date,">="&R_Mois,EMP_Date,"<"&EDATE(R_Mois,1))=0,"",COUNTIFS(EMP_Livre,$E73,EMP_Date,">="&R_Mois,EMP_Date,"<"&EDATE(R_Mois,1))+ROW()/100000))
N74: =IF($E74="","",COUNTIFS(EMP_Livre,$E74,EMP_Retour,"")) | O74: =IF($E74="","",$L74-$N74) | P74: =IF($E74="","",COUNTIF(EMP_Livre,$E74)) | Q74: =IF($E74="","",IF($O74<=0,"Indisponible",IF(AND($O74=1,$L74>1),"Dernier exemplaire","Disponible"))) | S74: =IF($E74="","",$P74+ROW()/100000) | T74: =IF(OR(Q_Rech="",$E74=""),"",IF(ISNUMBER(SEARCH(Q_Rech,$E74&" "&$F74&" "&$G74&" "&$H74&" "&$I74)),COUNT($T$6:$T73)+1,"")) | U74: =IF($E74="","",IF(COUNTIFS(EMP_Livre,$E74,EMP_Date,">="&R_Mois,EMP_Date,"<"&EDATE(R_Mois,1))=0,"",COUNTIFS(EMP_Livre,$E74,EMP_Date,">="&R_Mois,EMP_Date,"<"&EDATE(R_Mois,1))+ROW()/100000))
N75: =IF($E75="","",COUNTIFS(EMP_Livre,$E75,EMP_Retour,"")) | O75: =IF($E75="","",$L75-$N75) | P75: =IF($E75="","",COUNTIF(EMP_Livre,$E75)) | Q75: =IF($E75="","",IF($O75<=0,"Indisponible",IF(AND($O75=1,$L75>1),"Dernier exemplaire","Disponible"))) | S75: =IF($E75="","",$P75+ROW()/100000) | T75: =IF(OR(Q_Rech="",$E75=""),"",IF(ISNUMBER(SEARCH(Q_Rech,$E75&" "&$F75&" "&$G75&" "&$H75&" "&$I75)),COUNT($T$6:$T74)+1,"")) | U75: =IF($E75="","",IF(COUNTIFS(EMP_Livre,$E75,EMP_Date,">="&R_Mois,EMP_Date,"<"&EDATE(R_Mois,1))=0,"",COUNTIFS(EMP_Livre,$E75,EMP_Date,">="&R_Mois,EMP_Date,"<"&EDATE(R_Mois,1))+ROW()/100000))
N76: =IF($E76="","",COUNTIFS(EMP_Livre,$E76,EMP_Retour,"")) | O76: =IF($E76="","",$L76-$N76) | P76: =IF($E76="","",COUNTIF(EMP_Livre,$E76)) | Q76: =IF($E76="","",IF($O76<=0,"Indisponible",IF(AND($O76=1,$L76>1),"Dernier exemplaire","Disponible"))) | S76: =IF($E76="","",$P76+ROW()/100000) | T76: =IF(OR(Q_Rech="",$E76=""),"",IF(ISNUMBER(SEARCH(Q_Rech,$E76&" "&$F76&" "&$G76&" "&$H76&" "&$I76)),COUNT($T$6:$T75)+1,"")) | U76: =IF($E76="","",IF(COUNTIFS(EMP_Livre,$E76,EMP_Date,">="&R_Mois,EMP_Date,"<"&EDATE(R_Mois,1))=0,"",COUNTIFS(EMP_Livre,$E76,EMP_Date,">="&R_Mois,EMP_Date,"<"&EDATE(R_Mois,1))+ROW()/100000))
N77: =IF($E77="","",COUNTIFS(EMP_Livre,$E77,EMP_Retour,"")) | O77: =IF($E77="","",$L77-$N77) | P77: =IF($E77="","",COUNTIF(EMP_Livre,$E77)) | Q77: =IF($E77="","",IF($O77<=0,"Indisponible",IF(AND($O77=1,$L77>1),"Dernier exemplaire","Disponible"))) | S77: =IF($E77="","",$P77+ROW()/100000) | T77: =IF(OR(Q_Rech="",$E77=""),"",IF(ISNUMBER(SEARCH(Q_Rech,$E77&" "&$F77&" "&$G77&" "&$H77&" "&$I77)),COUNT($T$6:$T76)+1,"")) | U77: =IF($E77="","",IF(COUNTIFS(EMP_Livre,$E77,EMP_Date,">="&R_Mois,EMP_Date,"<"&EDATE(R_Mois,1))=0,"",COUNTIFS(EMP_Livre,$E77,EMP_Date,">="&R_Mois,EMP_Date,"<"&EDATE(R_Mois,1))+ROW()/100000))
N78: =IF($E78="","",COUNTIFS(EMP_Livre,$E78,EMP_Retour,"")) | O78: =IF($E78="","",$L78-$N78) | P78: =IF($E78="","",COUNTIF(EMP_Livre,$E78)) | Q78: =IF($E78="","",IF($O78<=0,"Indisponible",IF(AND($O78=1,$L78>1),"Dernier exemplaire","Disponible"))) | S78: =IF($E78="","",$P78+ROW()/100000) | T78: =IF(OR(Q_Rech="",$E78=""),"",IF(ISNUMBER(SEARCH(Q_Rech,$E78&" "&$F78&" "&$G78&" "&$H78&" "&$I78)),COUNT($T$6:$T77)+1,"")) | U78: =IF($E78="","",IF(COUNTIFS(EMP_Livre,$E78,EMP_Date,">="&R_Mois,EMP_Date,"<"&EDATE(R_Mois,1))=0,"",COUNTIFS(EMP_Livre,$E78,EMP_Date,">="&R_Mois,EMP_Date,"<"&EDATE(R_Mois,1))+ROW()/100000))
... N306: =IF($E306="","",COUNTIFS(EMP_Livre,$E306,EMP_Retour,"")) | O306: =IF($E306="","",$L306-$N306) | P306: =IF($E306="","",COUNTIF(EMP_Livre,$E306)) | Q306: =IF($E306="","",IF($O306<=0,"Indisponible",IF(AND($O306=1,$L306>1),"Dernier exemplaire","Disponible"))) | S306: =IF($E306="","",$P306+ROW()/100000) | T306: =IF(OR(Q_Rech="",$E306=""),"",IF(ISNUMBER(SEARCH(Q_Rech,$E306&" "&$F306&" "&$G306&" "&$H306&" "&$I306)),COUNT($T$6:$T305)+1,"")) | U306: =IF($E306="","",IF(COUNTIFS(EMP_Livre,$E306,EMP_Date,">="&R_Mois,EMP_Date,"<"&EDATE(R_Mois,1))=0,"",COUNTIFS(EMP_Livre,$E306,EMP_Date,">="&R_Mois,EMP_Date,"<"&EDATE(R_Mois,1))+ROW()/100000))

Sheet Membres
E2: 👥 Membres | K2: =HYPERLINK("#'Tableau de bord'!A1","⌂ Tableau de bord") | M2: =HYPERLINK("#'Membres'!E"&(7+COUNTIF(MEM_ID,"?*")),"＋ Nouveau membre")
E3: Élèves, enseignants et personnel inscrits à la bibliothèque.
E4: =COUNTIF(MEM_ID,"?*")&" membres" | G4: =COUNTIF(MEM_Type,"Élève")&" élèves" | I4: =COUNTIF(MEM_Type,"Enseignant")&" enseignants" | K4: =COUNTIF(MEM_Statut,"En retard")&" en retard"
E6: ID membre | F6: Nom complet | G6: Type | H6: Classe | I6: Sexe | J6: Date d'inscription | K6: Emprunts en cours | L6: En retard | M6: Amendes dues | N6: Statut
E7: MEM-001 | F7: Naomie Kambale | G7: Élève | H7: 1ère Primaire | I7: F | J7: 45909 | K7: =IF($E7="","",COUNTIFS(EMP_Membre,$E7,EMP_Retour,"")) | L7: =IF($E7="","",COUNTIFS(EMP_Membre,$E7,EMP_Statut,"En retard")) | M7: =IF($E7="","",SUMIFS(EMP_Amende,EMP_Membre,$E7,EMP_Paye,"<>Oui")) | N7: =IF($E7="","",IF($L7>0,"En retard",IF($K7>=P_Max,"Limite atteinte","Actif"))) | P7: =IF(OR(Q_Rech="",$E7=""),"",IF(ISNUMBER(SEARCH(Q_Rech,$E7&" "&$F7&" "&$H7)),COUNT($P$6:$P6)+1,""))
B8: =HYPERLINK("#'Tableau de bord'!A1","▦ Tableau de bord") | E8: MEM-002 | F8: Caleb Byamungu | G8: Élève | H8: 2ème Primaire | I8: M | J8: 45907 | K8: =IF($E8="","",COUNTIFS(EMP_Membre,$E8,EMP_Retour,"")) | L8: =IF($E8="","",COUNTIFS(EMP_Membre,$E8,EMP_Statut,"En retard")) | M8: =IF($E8="","",SUMIFS(EMP_Amende,EMP_Membre,$E8,EMP_Paye,"<>Oui")) | N8: =IF($E8="","",IF($L8>0,"En retard",IF($K8>=P_Max,"Limite atteinte","Actif"))) | P8: =IF(OR(Q_Rech="",$E8=""),"",IF(ISNUMBER(SEARCH(Q_Rech,$E8&" "&$F8&" "&$H8)),COUNT($P$6:$P7)+1,""))
B9: =HYPERLINK("#'Livres'!A1","📚 Livres") | E9: MEM-003 | F9: Chancelle Mirindi | G9: Élève | H9: 3ème Primaire | I9: F | J9: 45918 | K9: =IF($E9="","",COUNTIFS(EMP_Membre,$E9,EMP_Retour,"")) | L9: =IF($E9="","",COUNTIFS(EMP_Membre,$E9,EMP_Statut,"En retard")) | M9: =IF($E9="","",SUMIFS(EMP_Amende,EMP_Membre,$E9,EMP_Paye,"<>Oui")) | N9: =IF($E9="","",IF($L9>0,"En retard",IF($K9>=P_Max,"Limite atteinte","Actif"))) | P9: =IF(OR(Q_Rech="",$E9=""),"",IF(ISNUMBER(SEARCH(Q_Rech,$E9&" "&$F9&" "&$H9)),COUNT($P$6:$P8)+1,""))
B10: =HYPERLINK("#'Membres'!A1","👥 Membres") | E10: MEM-004 | F10: Amani Mirindi | G10: Élève | H10: 4ème Primaire | I10: M | J10: 45905 | K10: =IF($E10="","",COUNTIFS(EMP_Membre,$E10,EMP_Retour,"")) | L10: =IF($E10="","",COUNTIFS(EMP_Membre,$E10,EMP_Statut,"En retard")) | M10: =IF($E10="","",SUMIFS(EMP_Amende,EMP_Membre,$E10,EMP_Paye,"<>Oui")) | N10: =IF($E10="","",IF($L10>0,"En retard",IF($K10>=P_Max,"Limite atteinte","Actif"))) | P10: =IF(OR(Q_Rech="",$E10=""),"",IF(ISNUMBER(SEARCH(Q_Rech,$E10&" "&$F10&" "&$H10)),COUNT($P$6:$P9)+1,""))
B11: =HYPERLINK("#'Emprunts'!A1","🔄 Emprunts") | E11: MEM-005 | F11: Merveille Balume | G11: Élève | H11: 5ème Primaire | I11: F | J11: 45905 | K11: =IF($E11="","",COUNTIFS(EMP_Membre,$E11,EMP_Retour,"")) | L11: =IF($E11="","",COUNTIFS(EMP_Membre,$E11,EMP_Statut,"En retard")) | M11: =IF($E11="","",SUMIFS(EMP_Amende,EMP_Membre,$E11,EMP_Paye,"<>Oui")) | N11: =IF($E11="","",IF($L11>0,"En retard",IF($K11>=P_Max,"Limite atteinte","Actif"))) | P11: =IF(OR(Q_Rech="",$E11=""),"",IF(ISNUMBER(SEARCH(Q_Rech,$E11&" "&$F11&" "&$H11)),COUNT($P$6:$P10)+1,""))
B12: =HYPERLINK("#'Fournitures'!A1","📦 Fournitures") | E12: MEM-006 | F12: Esther Bisimwa | G12: Élève | H12: 6ème Primaire | I12: F | J12: 45910 | K12: =IF($E12="","",COUNTIFS(EMP_Membre,$E12,EMP_Retour,"")) | L12: =IF($E12="","",COUNTIFS(EMP_Membre,$E12,EMP_Statut,"En retard")) | M12: =IF($E12="","",SUMIFS(EMP_Amende,EMP_Membre,$E12,EMP_Paye,"<>Oui")) | N12: =IF($E12="","",IF($L12>0,"En retard",IF($K12>=P_Max,"Limite atteinte","Actif"))) | P12: =IF(OR(Q_Rech="",$E12=""),"",IF(ISNUMBER(SEARCH(Q_Rech,$E12&" "&$F12&" "&$H12)),COUNT($P$6:$P11)+1,""))
B13: =HYPERLINK("#'Mouvements'!A1","↕ Mouvements de stock") | E13: MEM-007 | F13: Ruth Zawadi | G13: Élève | H13: 7ème EB | I13: F | J13: 45912 | K13: =IF($E13="","",COUNTIFS(EMP_Membre,$E13,EMP_Retour,"")) | L13: =IF($E13="","",COUNTIFS(EMP_Membre,$E13,EMP_Statut,"En retard")) | M13: =IF($E13="","",SUMIFS(EMP_Amende,EMP_Membre,$E13,EMP_Paye,"<>Oui")) | N13: =IF($E13="","",IF($L13>0,"En retard",IF($K13>=P_Max,"Limite atteinte","Actif"))) | P13: =IF(OR(Q_Rech="",$E13=""),"",IF(ISNUMBER(SEARCH(Q_Rech,$E13&" "&$F13&" "&$H13)),COUNT($P$6:$P12)+1,""))
B14: =HYPERLINK("#'Recherche'!A1","🔍 Recherche") | E14: MEM-008 | F14: Patrick Balume | G14: Élève | H14: 8ème EB | I14: M | J14: 45918 | K14: =IF($E14="","",COUNTIFS(EMP_Membre,$E14,EMP_Retour,"")) | L14: =IF($E14="","",COUNTIFS(EMP_Membre,$E14,EMP_Statut,"En retard")) | M14: =IF($E14="","",SUMIFS(EMP_Amende,EMP_Membre,$E14,EMP_Paye,"<>Oui")) | N14: =IF($E14="","",IF($L14>0,"En retard",IF($K14>=P_Max,"Limite atteinte","Actif"))) | P14: =IF(OR(Q_Rech="",$E14=""),"",IF(ISNUMBER(SEARCH(Q_Rech,$E14&" "&$F14&" "&$H14)),COUNT($P$6:$P13)+1,""))
B15: =HYPERLINK("#'Rapport mensuel'!A1","🖨 Rapport mensuel") | E15: MEM-009 | F15: Fiston Balume | G15: Élève | H15: 1ère Humanités | I15: M | J15: 45903 | K15: =IF($E15="","",COUNTIFS(EMP_Membre,$E15,EMP_Retour,"")) | L15: =IF($E15="","",COUNTIFS(EMP_Membre,$E15,EMP_Statut,"En retard")) | M15: =IF($E15="","",SUMIFS(EMP_Amende,EMP_Membre,$E15,EMP_Paye,"<>Oui")) | N15: =IF($E15="","",IF($L15>0,"En retard",IF($K15>=P_Max,"Limite atteinte","Actif"))) | P15: =IF(OR(Q_Rech="",$E15=""),"",IF(ISNUMBER(SEARCH(Q_Rech,$E15&" "&$F15&" "&$H15)),COUNT($P$6:$P14)+1,""))
B16: =HYPERLINK("#'Paramètres'!A1","⚙ Paramètres") | E16: MEM-010 | F16: Josué Tshibanda | G16: Élève | H16: 2ème Humanités | I16: M | J16: 45910 | K16: =IF($E16="","",COUNTIFS(EMP_Membre,$E16,EMP_Retour,"")) | L16: =IF($E16="","",COUNTIFS(EMP_Membre,$E16,EMP_Statut,"En retard")) | M16: =IF($E16="","",SUMIFS(EMP_Amende,EMP_Membre,$E16,EMP_Paye,"<>Oui")) | N16: =IF($E16="","",IF($L16>0,"En retard",IF($K16>=P_Max,"Limite atteinte","Actif"))) | P16: =IF(OR(Q_Rech="",$E16=""),"",IF(ISNUMBER(SEARCH(Q_Rech,$E16&" "&$F16&" "&$H16)),COUNT($P$6:$P15)+1,""))
E17: MEM-011 | F17: Neema Mugisho | G17: Élève | H17: 3ème Humanités | I17: F | J17: 45912 | K17: =IF($E17="","",COUNTIFS(EMP_Membre,$E17,EMP_Retour,"")) | L17: =IF($E17="","",COUNTIFS(EMP_Membre,$E17,EMP_Statut,"En retard")) | M17: =IF($E17="","",SUMIFS(EMP_Amende,EMP_Membre,$E17,EMP_Paye,"<>Oui")) | N17: =IF($E17="","",IF($L17>0,"En retard",IF($K17>=P_Max,"Limite atteinte","Actif"))) | P17: =IF(OR(Q_Rech="",$E17=""),"",IF(ISNUMBER(SEARCH(Q_Rech,$E17&" "&$F17&" "&$H17)),COUNT($P$6:$P16)+1,""))
E18: MEM-012 | F18: Sarah Mukendi | G18: Élève | H18: 4ème Humanités | I18: F | J18: 45919 | K18: =IF($E18="","",COUNTIFS(EMP_Membre,$E18,EMP_Retour,"")) | L18: =IF($E18="","",COUNTIFS(EMP_Membre,$E18,EMP_Statut,"En retard")) | M18: =IF($E18="","",SUMIFS(EMP_Amende,EMP_Membre,$E18,EMP_Paye,"<>Oui")) | N18: =IF($E18="","",IF($L18>0,"En retard",IF($K18>=P_Max,"Limite atteinte","Actif"))) | P18: =IF(OR(Q_Rech="",$E18=""),"",IF(ISNUMBER(SEARCH(Q_Rech,$E18&" "&$F18&" "&$H18)),COUNT($P$6:$P17)+1,""))
E19: MEM-013 | F19: Isaac Mugisho | G19: Élève | H19: 1ère Primaire | I19: M | J19: 45905 | K19: =IF($E19="","",COUNTIFS(EMP_Membre,$E19,EMP_Retour,"")) | L19: =IF($E19="","",COUNTIFS(EMP_Membre,$E19,EMP_Statut,"En retard")) | M19: =IF($E19="","",SUMIFS(EMP_Amende,EMP_Membre,$E19,EMP_Paye,"<>Oui")) | N19: =IF($E19="","",IF($L19>0,"En retard",IF($K19>=P_Max,"Limite atteinte","Actif"))) | P19: =IF(OR(Q_Rech="",$E19=""),"",IF(ISNUMBER(SEARCH(Q_Rech,$E19&" "&$F19&" "&$H19)),COUNT($P$6:$P18)+1,""))
E20: MEM-014 | F20: Grâce Bisimwa | G20: Élève | H20: 2ème Primaire | I20: F | J20: 45919 | K20: =IF($E20="","",COUNTIFS(EMP_Membre,$E20,EMP_Retour,"")) | L20: =IF($E20="","",COUNTIFS(EMP_Membre,$E20,EMP_Statut,"En retard")) | M20: =IF($E20="","",SUMIFS(EMP_Amende,EMP_Membre,$E20,EMP_Paye,"<>Oui")) | N20: =IF($E20="","",IF($L20>0,"En retard",IF($K20>=P_Max,"Limite atteinte","Actif"))) | P20: =IF(OR(Q_Rech="",$E20=""),"",IF(ISNUMBER(SEARCH(Q_Rech,$E20&" "&$F20&" "&$H20)),COUNT($P$6:$P19)+1,""))
E21: MEM-015 | F21: Neema Safari | G21: Élève | H21: 3ème Primaire | I21: F | J21: 45920 | K21: =IF($E21="","",COUNTIFS(EMP_Membre,$E21,EMP_Retour,"")) | L21: =IF($E21="","",COUNTIFS(EMP_Membre,$E21,EMP_Statut,"En retard")) | M21: =IF($E21="","",SUMIFS(EMP_Amende,EMP_Membre,$E21,EMP_Paye,"<>Oui")) | N21: =IF($E21="","",IF($L21>0,"En retard",IF($K21>=P_Max,"Limite atteinte","Actif"))) | P21: =IF(OR(Q_Rech="",$E21=""),"",IF(ISNUMBER(SEARCH(Q_Rech,$E21&" "&$F21&" "&$H21)),COUNT($P$6:$P20)+1,""))
E22: MEM-016 | F22: Daniel Tshibanda | G22: Élève | H22: 4ème Primaire | I22: M | J22: 45906 | K22: =IF($E22="","",COUNTIFS(EMP_Membre,$E22,EMP_Retour,"")) | L22: =IF($E22="","",COUNTIFS(EMP_Membre,$E22,EMP_Statut,"En retard")) | M22: =IF($E22="","",SUMIFS(EMP_Amende,EMP_Membre,$E22,EMP_Paye,"<>Oui")) | N22: =IF($E22="","",IF($L22>0,"En retard",IF($K22>=P_Max,"Limite atteinte","Actif"))) | P22: =IF(OR(Q_Rech="",$E22=""),"",IF(ISNUMBER(SEARCH(Q_Rech,$E22&" "&$F22&" "&$H22)),COUNT($P$6:$P21)+1,""))
E23: MEM-017 | F23: Neema Mirindi | G23: Élève | H23: 5ème Primaire | I23: F | J23: 45913 | K23: =IF($E23="","",COUNTIFS(EMP_Membre,$E23,EMP_Retour,"")) | L23: =IF($E23="","",COUNTIFS(EMP_Membre,$E23,EMP_Statut,"En retard")) | M23: =IF($E23="","",SUMIFS(EMP_Amende,EMP_Membre,$E23,EMP_Paye,"<>Oui")) | N23: =IF($E23="","",IF($L23>0,"En retard",IF($K23>=P_Max,"Limite atteinte","Actif"))) | P23: =IF(OR(Q_Rech="",$E23=""),"",IF(ISNUMBER(SEARCH(Q_Rech,$E23&" "&$F23&" "&$H23)),COUNT($P$6:$P22)+1,""))
E24: MEM-018 | F24: Neema Wabo | G24: Élève | H24: 6ème Primaire | I24: F | J24: 45908 | K24: =IF($E24="","",COUNTIFS(EMP_Membre,$E24,EMP_Retour,"")) | L24: =IF($E24="","",COUNTIFS(EMP_Membre,$E24,EMP_Statut,"En retard")) | M24: =IF($E24="","",SUMIFS(EMP_Amende,EMP_Membre,$E24,EMP_Paye,"<>Oui")) | N24: =IF($E24="","",IF($L24>0,"En retard",IF($K24>=P_Max,"Limite atteinte","Actif"))) | P24: =IF(OR(Q_Rech="",$E24=""),"",IF(ISNUMBER(SEARCH(Q_Rech,$E24&" "&$F24&" "&$H24)),COUNT($P$6:$P23)+1,""))
E25: MEM-019 | F25: David Paluku | G25: Élève | H25: 7ème EB | I25: M | J25: 45913 | K25: =IF($E25="","",COUNTIFS(EMP_Membre,$E25,EMP_Retour,"")) | L25: =IF($E25="","",COUNTIFS(EMP_Membre,$E25,EMP_Statut,"En retard")) | M25: =IF($E25="","",SUMIFS(EMP_Amende,EMP_Membre,$E25,EMP_Paye,"<>Oui")) | N25: =IF($E25="","",IF($L25>0,"En retard",IF($K25>=P_Max,"Limite atteinte","Actif"))) | P25: =IF(OR(Q_Rech="",$E25=""),"",IF(ISNUMBER(SEARCH(Q_Rech,$E25&" "&$F25&" "&$H25)),COUNT($P$6:$P24)+1,""))
E26: MEM-020 | F26: Ornella Bisimwa | G26: Élève | H26: 8ème EB | I26: F | J26: 45909 | K26: =IF($E26="","",COUNTIFS(EMP_Membre,$E26,EMP_Retour,"")) | L26: =IF($E26="","",COUNTIFS(EMP_Membre,$E26,EMP_Statut,"En retard")) | M26: =IF($E26="","",SUMIFS(EMP_Amende,EMP_Membre,$E26,EMP_Paye,"<>Oui")) | N26: =IF($E26="","",IF($L26>0,"En retard",IF($K26>=P_Max,"Limite atteinte","Actif"))) | P26: =IF(OR(Q_Rech="",$E26=""),"",IF(ISNUMBER(SEARCH(Q_Rech,$E26&" "&$F26&" "&$H26)),COUNT($P$6:$P25)+1,""))
E27: MEM-021 | F27: Sarah Baraka | G27: Élève | H27: 1ère Humanités | I27: F | J27: 45915 | K27: =IF($E27="","",COUNTIFS(EMP_Membre,$E27,EMP_Retour,"")) | L27: =IF($E27="","",COUNTIFS(EMP_Membre,$E27,EMP_Statut,"En retard")) | M27: =IF($E27="","",SUMIFS(EMP_Amende,EMP_Membre,$E27,EMP_Paye,"<>Oui")) | N27: =IF($E27="","",IF($L27>0,"En retard",IF($K27>=P_Max,"Limite atteinte","Actif"))) | P27: =IF(OR(Q_Rech="",$E27=""),"",IF(ISNUMBER(SEARCH(Q_Rech,$E27&" "&$F27&" "&$H27)),COUNT($P$6:$P26)+1,""))
E28: MEM-022 | F28: Bahati Baraka | G28: Élève | H28: 2ème Humanités | I28: M | J28: 45912 | K28: =IF($E28="","",COUNTIFS(EMP_Membre,$E28,EMP_Retour,"")) | L28: =IF($E28="","",COUNTIFS(EMP_Membre,$E28,EMP_Statut,"En retard")) | M28: =IF($E28="","",SUMIFS(EMP_Amende,EMP_Membre,$E28,EMP_Paye,"<>Oui")) | N28: =IF($E28="","",IF($L28>0,"En retard",IF($K28>=P_Max,"Limite atteinte","Actif"))) | P28: =IF(OR(Q_Rech="",$E28=""),"",IF(ISNUMBER(SEARCH(Q_Rech,$E28&" "&$F28&" "&$H28)),COUNT($P$6:$P27)+1,""))
... E46: MEM-040 | F46: Ornella Kalume | G46: Personnel | H46: Personnel | I46: F | J46: 46302 | K46: =IF($E46="","",COUNTIFS(EMP_Membre,$E46,EMP_Retour,"")) | L46: =IF($E46="","",COUNTIFS(EMP_Membre,$E46,EMP_Statut,"En retard")) | M46: =IF($E46="","",SUMIFS(EMP_Amende,EMP_Membre,$E46,EMP_Paye,"<>Oui")) | N46: =IF($E46="","",IF($L46>0,"En retard",IF($K46>=P_Max,"Limite atteinte","Actif"))) | P46: =IF(OR(Q_Rech="",$E46=""),"",IF(ISNUMBER(SEARCH(Q_Rech,$E46&" "&$F46&" "&$H46)),COUNT($P$6:$P45)+1,""))
K47: =IF($E47="","",COUNTIFS(EMP_Membre,$E47,EMP_Retour,"")) | L47: =IF($E47="","",COUNTIFS(EMP_Membre,$E47,EMP_Statut,"En retard")) | M47: =IF($E47="","",SUMIFS(EMP_Amende,EMP_Membre,$E47,EMP_Paye,"<>Oui")) | N47: =IF($E47="","",IF($L47>0,"En retard",IF($K47>=P_Max,"Limite atteinte","Actif"))) | P47: =IF(OR(Q_Rech="",$E47=""),"",IF(ISNUMBER(SEARCH(Q_Rech,$E47&" "&$F47&" "&$H47)),COUNT($P$6:$P46)+1,""))
K48: =IF($E48="","",COUNTIFS(EMP_Membre,$E48,EMP_Retour,"")) | L48: =IF($E48="","",COUNTIFS(EMP_Membre,$E48,EMP_Statut,"En retard")) | M48: =IF($E48="","",SUMIFS(EMP_Amende,EMP_Membre,$E48,EMP_Paye,"<>Oui")) | N48: =IF($E48="","",IF($L48>0,"En retard",IF($K48>=P_Max,"Limite atteinte","Actif"))) | P48: =IF(OR(Q_Rech="",$E48=""),"",IF(ISNUMBER(SEARCH(Q_Rech,$E48&" "&$F48&" "&$H48)),COUNT($P$6:$P47)+1,""))
K49: =IF($E49="","",COUNTIFS(EMP_Membre,$E49,EMP_Retour,"")) | L49: =IF($E49="","",COUNTIFS(EMP_Membre,$E49,EMP_Statut,"En retard")) | M49: =IF($E49="","",SUMIFS(EMP_Amende,EMP_Membre,$E49,EMP_Paye,"<>Oui")) | N49: =IF($E49="","",IF($L49>0,"En retard",IF($K49>=P_Max,"Limite atteinte","Actif"))) | P49: =IF(OR(Q_Rech="",$E49=""),"",IF(ISNUMBER(SEARCH(Q_Rech,$E49&" "&$F49&" "&$H49)),COUNT($P$6:$P48)+1,""))
K50: =IF($E50="","",COUNTIFS(EMP_Membre,$E50,EMP_Retour,"")) | L50: =IF($E50="","",COUNTIFS(EMP_Membre,$E50,EMP_Statut,"En retard")) | M50: =IF($E50="","",SUMIFS(EMP_Amende,EMP_Membre,$E50,EMP_Paye,"<>Oui")) | N50: =IF($E50="","",IF($L50>0,"En retard",IF($K50>=P_Max,"Limite atteinte","Actif"))) | P50: =IF(OR(Q_Rech="",$E50=""),"",IF(ISNUMBER(SEARCH(Q_Rech,$E50&" "&$F50&" "&$H50)),COUNT($P$6:$P49)+1,""))
K51: =IF($E51="","",COUNTIFS(EMP_Membre,$E51,EMP_Retour,"")) | L51: =IF($E51="","",COUNTIFS(EMP_Membre,$E51,EMP_Statut,"En retard")) | M51: =IF($E51="","",SUMIFS(EMP_Amende,EMP_Membre,$E51,EMP_Paye,"<>Oui")) | N51: =IF($E51="","",IF($L51>0,"En retard",IF($K51>=P_Max,"Limite atteinte","Actif"))) | P51: =IF(OR(Q_Rech="",$E51=""),"",IF(ISNUMBER(SEARCH(Q_Rech,$E51&" "&$F51&" "&$H51)),COUNT($P$6:$P50)+1,""))
K52: =IF($E52="","",COUNTIFS(EMP_Membre,$E52,EMP_Retour,"")) | L52: =IF($E52="","",COUNTIFS(EMP_Membre,$E52,EMP_Statut,"En retard")) | M52: =IF($E52="","",SUMIFS(EMP_Amende,EMP_Membre,$E52,EMP_Paye,"<>Oui")) | N52: =IF($E52="","",IF($L52>0,"En retard",IF($K52>=P_Max,"Limite atteinte","Actif"))) | P52: =IF(OR(Q_Rech="",$E52=""),"",IF(ISNUMBER(SEARCH(Q_Rech,$E52&" "&$F52&" "&$H52)),COUNT($P$6:$P51)+1,""))
K53: =IF($E53="","",COUNTIFS(EMP_Membre,$E53,EMP_Retour,"")) | L53: =IF($E53="","",COUNTIFS(EMP_Membre,$E53,EMP_Statut,"En retard")) | M53: =IF($E53="","",SUMIFS(EMP_Amende,EMP_Membre,$E53,EMP_Paye,"<>Oui")) | N53: =IF($E53="","",IF($L53>0,"En retard",IF($K53>=P_Max,"Limite atteinte","Actif"))) | P53: =IF(OR(Q_Rech="",$E53=""),"",IF(ISNUMBER(SEARCH(Q_Rech,$E53&" "&$F53&" "&$H53)),COUNT($P$6:$P52)+1,""))
K54: =IF($E54="","",COUNTIFS(EMP_Membre,$E54,EMP_Retour,"")) | L54: =IF($E54="","",COUNTIFS(EMP_Membre,$E54,EMP_Statut,"En retard")) | M54: =IF($E54="","",SUMIFS(EMP_Amende,EMP_Membre,$E54,EMP_Paye,"<>Oui")) | N54: =IF($E54="","",IF($L54>0,"En retard",IF($K54>=P_Max,"Limite atteinte","Actif"))) | P54: =IF(OR(Q_Rech="",$E54=""),"",IF(ISNUMBER(SEARCH(Q_Rech,$E54&" "&$F54&" "&$H54)),COUNT($P$6:$P53)+1,""))
K55: =IF($E55="","",COUNTIFS(EMP_Membre,$E55,EMP_Retour,"")) | L55: =IF($E55="","",COUNTIFS(EMP_Membre,$E55,EMP_Statut,"En retard")) | M55: =IF($E55="","",SUMIFS(EMP_Amende,EMP_Membre,$E55,EMP_Paye,"<>Oui")) | N55: =IF($E55="","",IF($L55>0,"En retard",IF($K55>=P_Max,"Limite atteinte","Actif"))) | P55: =IF(OR(Q_Rech="",$E55=""),"",IF(ISNUMBER(SEARCH(Q_Rech,$E55&" "&$F55&" "&$H55)),COUNT($P$6:$P54)+1,""))
K56: =IF($E56="","",COUNTIFS(EMP_Membre,$E56,EMP_Retour,"")) | L56: =IF($E56="","",COUNTIFS(EMP_Membre,$E56,EMP_Statut,"En retard")) | M56: =IF($E56="","",SUMIFS(EMP_Amende,EMP_Membre,$E56,EMP_Paye,"<>Oui")) | N56: =IF($E56="","",IF($L56>0,"En retard",IF($K56>=P_Max,"Limite atteinte","Actif"))) | P56: =IF(OR(Q_Rech="",$E56=""),"",IF(ISNUMBER(SEARCH(Q_Rech,$E56&" "&$F56&" "&$H56)),COUNT($P$6:$P55)+1,""))
K57: =IF($E57="","",COUNTIFS(EMP_Membre,$E57,EMP_Retour,"")) | L57: =IF($E57="","",COUNTIFS(EMP_Membre,$E57,EMP_Statut,"En retard")) | M57: =IF($E57="","",SUMIFS(EMP_Amende,EMP_Membre,$E57,EMP_Paye,"<>Oui")) | N57: =IF($E57="","",IF($L57>0,"En retard",IF($K57>=P_Max,"Limite atteinte","Actif"))) | P57: =IF(OR(Q_Rech="",$E57=""),"",IF(ISNUMBER(SEARCH(Q_Rech,$E57&" "&$F57&" "&$H57)),COUNT($P$6:$P56)+1,""))
K58: =IF($E58="","",COUNTIFS(EMP_Membre,$E58,EMP_Retour,"")) | L58: =IF($E58="","",COUNTIFS(EMP_Membre,$E58,EMP_Statut,"En retard")) | M58: =IF($E58="","",SUMIFS(EMP_Amende,EMP_Membre,$E58,EMP_Paye,"<>Oui")) | N58: =IF($E58="","",IF($L58>0,"En retard",IF($K58>=P_Max,"Limite atteinte","Actif"))) | P58: =IF(OR(Q_Rech="",$E58=""),"",IF(ISNUMBER(SEARCH(Q_Rech,$E58&" "&$F58&" "&$H58)),COUNT($P$6:$P57)+1,""))
... K306: =IF($E306="","",COUNTIFS(EMP_Membre,$E306,EMP_Retour,"")) | L306: =IF($E306="","",COUNTIFS(EMP_Membre,$E306,EMP_Statut,"En retard")) | M306: =IF($E306="","",SUMIFS(EMP_Amende,EMP_Membre,$E306,EMP_Paye,"<>Oui")) | N306: =IF($E306="","",IF($L306>0,"En retard",IF($K306>=P_Max,"Limite atteinte","Actif"))) | P306: =IF(OR(Q_Rech="",$E306=""),"",IF(ISNUMBER(SEARCH(Q_Rech,$E306&" "&$F306&" "&$H306)),COUNT($P$6:$P305)+1,""))

Sheet Emprunts
E2: 🔄 Emprunts & retours | M2: =HYPERLINK("#'Tableau de bord'!A1","⌂ Tableau de bord") | O2: =HYPERLINK("#'Emprunts'!F"&(7+COUNTIF(EMP_Date,"?*")),"＋ Nouvel emprunt")
E3: Nouvel emprunt : date, ID membre, code livre. Retour : saisissez simplement la date de retour.
E4: =COUNTIFS(EMP_Livre,"?*",EMP_Retour,"")&" en cours" | G4: =COUNTIF(EMP_Statut,"En retard")&" en retard" | I4: =COUNTIF(EMP_Statut,"Rendu*")&" rendus" | K4: =FIXED(SUMIFS(EMP_Amende,EMP_Paye,"<>Oui"),0)&" FC dus"
E6: N° | F6: Date d'emprunt | G6: ID membre | H6: Nom du membre | I6: Code livre | J6: Titre du livre | K6: Retour prévu | L6: Date de retour | M6: Statut | N6: Jours de retard | O6: Amende | P6: Amende payée
E7: =IF($F7="","","EMP-"&TEXT(ROW()-6,"0000")) | F7: 45943 | G7: MEM-009 | H7: =IF($G7="","",IFERROR(INDEX(MEM_Nom,MATCH($G7,MEM_ID,0)),"⚠ ID inconnu")) | I7: LIV-011 | J7: =IF($I7="","",IFERROR(INDEX(LIV_Titre,MATCH($I7,LIV_Code,0)),"⚠ Code inconnu")) | K7: =IF($F7="","",$F7+P_Duree) | L7: 45952 | M7: =IF(OR($F7="",$I7=""),"",IF($L7<>"",IF($L7>$K7,"Rendu en retard","Rendu"),IF(TODAY()>$K7,"En retard","En cours"))) | N7: =IF(OR($F7="",$I7=""),"",MAX(0,IF($L7<>"",$L7,TODAY())-$K7)) | O7: =IF(OR($F7="",$I7=""),"",$N7*P_Amende) | R7: =IF($M7="En retard",$N7+ROW()/100000,"") | S7: =IF(OR($F7="",$I7=""),"",$F7+ROW()/100000) | T7: =IF($I7="","",IFERROR(INDEX(LIV_Cat,MATCH($I7,LIV_Code,0)),""))
